Workbook

Sheet Syllabus
A1: Syllabus Details
A3: Syllabus ID: | B3: 1977
A4: Syllabus Name: | B4: Nhập môn lập trình
A5: Course Name English: | B5: Programming Introduction
A6: Subject Code: | B6: COM108
A7: NoCredit: | B7: 3
A8: Degree Level: | B8: Cao đẳng
A9: Time Allocation: | B9: Tổng thời lượng: 75 giờ
B10: 1. Trên lớp: 36 giờ
B11: + Tích hợp (Script/Lab/Workshop/Casestudy, Quiz, Progress Test, Open Activity)
B12: 2. Bảo vệ, kiểm tra: 2 giờ
B13: + Bảo vệ assignment hoặc/và thi cuối môn: 2 giờ
B14: 3. Học qua hướng dẫn của hệ thống: 37 giờ
B15: + Học và trả lời câu hỏi trong video trước khi đến lớp
B16: + Thực hiện dự án môn học (Assignment, Project)
A17: Pre-Requisite:
A18: Description: | B18: Môn học này cung cấp cho người học những khái niệm cơ bản trong lập trình đồng như biến, biểu thức, lệnh, mảng, thuật toán… thời được sử dụng để định hướng chuyên ngành phù hợp với năng lực, sở thích của người học sau khi kết thúc học kỳ 1.
A19: StudentTasks: | B19: - Thực hiện các nhiệm vụ của sinh viên trước giờ học và sau giờ học được nêu chi tiết trong lịch trình học
B20: - Tích cực tham gia các hoạt động trong giờ học trên lớp
B21: - Thực hiện đầy đủ các nhiệm vụ giảng viên giao
B22: - Hoàn thiện và nộp đúng hạn Assignment theo từng giai đoạn và bản báo cáo Assignment cuối kỳ
B23: - Sử dụng giáo trình, các tài nguyên đi kèm (nếu có) và tìm kiếm thêm các tài nguyên tham khảo từ các nguồn khác nhau để hoàn thiện kiến thức
B24: - Truy cập website tài nguyên (http://flm.poly.edu.vn) để có thông tin và tài nguyên cập nhật nhất của khóa học
B25: - Truy cập website quản lý khóa học (http://ap.poly.edu.vn) để có lịch học và kết quả điểm
B26: - Truy cập website http://cms.poly.edu.vn để học các bài học online
B27: - Email cho giảng viên khi có câu hỏi thắc mắc ngoài giờ học.
A28: Tools: | B28: - CFree 5
A29: Scoring Scale: | B29: 10
A30: DecisionNo MM/dd/yyyy: | B30: 543/QĐ-CĐFPL dated 07/30/2025
A31: IsApproved: | B31: TRUE
A32: Note: | B32: 1. Điều kiện dự thi cuối môn:
B33: - Trung bình cộng (theo trọng số) các thành phần điểm quá trình tối thiểu là 5
B34: - Tham dự tối thiểu 80% số giờ trên lớp
B35: - Hoàn thành 100% các bài học online trên CMS
B36: 2. Điều kiện qua môn:
B37: - Điểm đánh giá cuối môn (Final Exam) tối thiểu là 5
B38: - Tổng điểm môn tối thiểu là 5
B39: 3. Xem thêm phần cơ cấu điểm đánh giá (Grading Structure)
A40: MinAvgMarkToPass: | B40: 5
A41: IsActive: | B41: TRUE
...

Sheet Materials
A1: MaterialDescription | B1: Author | C1: Publisher | D1: PublishedDate | E1: Edition | F1: ISBN | G1: IsMainMaterial | H1: IsHardCopy | I1: IsOnline | J1: Note
A2: Assignment:1 | J2: Doing at home
A3: Bài học online: 8 | J3: Online learning videos
A4: Bài giảng trên lớp: 8 | J4: Teaching & learning materials
A5: Lab: 8 | J5: Teaching & learning materials
A6: Slide (08 ppt) | J6: Teaching & learning materials
A7: https://freetuts.net/hoc-c/c-can-ban | J7: Internet

Sheet CLO
A1: CLO Name | B1: CLO Details
A2: CLO1 | B2: Hiểu rõ các vấn đề cơ bản của lập trình: Hiểu rõ các vấn đề cơ bản về lập trình; Hiểu rõ các khái niệm về C
A3: CLO2 | B3: Hiểu rõ các khái niệm về biến, hằng, toán tử, biểu thức: Hiểu rõ các khái niệm về biến, hằng; Hiểu rõ các khái niệm về toán tử, biêu thức
A4: CLO3 | B4: Vận dụng câu điều kiện vào các bài toán: Vận dụng câu lệnh if để làm các bài toán; Vận dụng câu lệnh switch để làm các bài toán
A5: CLO4 | B5: Vận dụng vòng lặp vào các bài toán: Vận dụng câu lệnh while, do whie để làm các bài toán; Vận dụng câu lệnh if để làm các bài toán; Vận dụng break, continue, goto để làm các bài toán
A6: CLO5 | B6: Hiểu rõ về mảng và vận dụng trong các bài toán: Vận dụng mảng 1 chiều để làm các bài toán; Vận dung mảng 2 chiều để làm các bài toán
A7: CLO6 | B7: Vận dụng các hàm thao tác chuỗi: Vận dụng các hàm thao tác chuỗi để làm các bài toán
A8: CLO7 | B8: Hiểu về cấu trúc và vận dụng trong các bài toán: Vận dụng cấu trúc Structure để làm các bài toán; Vận dung cấu trúc Union để làm các bài toán

Sheet Constructivist Question
A1: No | B1: SessionNo | C1: Name | D1: Detail

Sheet Schedule
A2: Session | B2: Topic | C2: Learning-Teaching Type | D2: LO | E2: ITU | F2: Student Materials | G2: S-Download | H2: Lecturer Materials | I2: T-Download | J2: Student's Tasks | K2: Lecturer Tasks | L2: URLs
A3: 1 | B3: Slide 1.1 - Tổng quan lập trình; Lab 1.1 | C3: Offline | D3: CLO1.1 | E3: IT | F3: Syllabus, Assignment, Slide1.1, | G3: link1 | H3: Syllabus, Assignment, Slide1.1, | I3: link1 | J3: - Giới thiệu Syllabus, | K3: - Giới thiệu Syllabus,
B4: - Giới thiệu tổng quan về khái niệm lập trình | F4: Online 1.1, | H4: Online 1.1, | J4: - Giới thiệu Assignment, | K4: - Giới thiệu Assignment,
B5: - Giới thiệu về ngôn ngữ lập trình C | F5: Lab1.1 | H5: Lab1.1 | J5: - Slide1.1. | K5: - Slide1.1.
B6: - Cài đặt công cụ học lập trình | J6: - Thực hành Lab1.1 | K6: - Thực hành Lab1.1
J7: * Phân bổ thời gian: | K7: * Thực hiện các công việc:
J8: + (1 giờ): Học theo sự giảng dạy của giảng viên | K8: + Hướng dẫn sinh viên thực hiện asm qua từng bài học
J9: + (1 giờ): Thực hành hoặc thảo luận tình huống | K9: + Thuyết giảng theo slide bài giảng
J10: + (30 phút): Xem bài thuyết giảng của giảng viên qua video trên LMS/CMS | K10: + Hướng dẫn, ôn bài, chỉ rõ những điểm quan trọng trong video
J11: + (1 giờ 30 phút): Thực hiện assignment
A12: 2 | B12: Slide 1.2 - Tổng quan lập trình; Lab 1.2 | C12: Offline | D12: CLO1.2 | E12: ITU | F12: Slide1.2, Online 1.2, | H12: Slide1.2, Online 1.2, | J12: - Review Slide 1.1, | K12: - Review Slide 1.1,
B13: - Cú pháp C cơ bản | F13: Lab1.2 | H13: Lab1.2 | J13: - Slide1.2 | K13: - Slide1.2
B14: - Kiểu dữ liệu | J14: - Thực hành Lab1.2 | K14: - Thực hành Lab1.2
J15: * Phân bổ thời gian: | K15: * Thực hiện các công việc:
J16: + (1 giờ): Học theo sự giảng dạy của giảng viên | K16: + Hướng dẫn sinh viên thực hiện asm qua từng bài học
J17: + (1 giờ): Thực hành hoặc thảo luận tình huống | K17: + Thuyết giảng theo slide bài giảng
J18: + (30 phút): Xem bài thuyết giảng của giảng viên qua video trên LMS/CMS | K18: + Hướng dẫn, ôn bài, chỉ rõ những điểm quan trọng trong video
J19: + (1 giờ 30 phút): Thực hiện assignment
A20: 3 | B20: Slide 2.1 - Các khái niệm cơ bản; Lab 2.1 | C20: Offline | D20: CLO2.1 | E20: TU | F20: Slide2.1, | H20: Slide2.1, | J20: - Review Slide 1.2, | K20: - Review Slide 1.2,
B21: - Biến | F21: Online 2.1, | H21: Online 2.1, | J21: - Slide2.1 | K21: - Slide2.1
B22: - Hằng số | F22: Lab2.1 | H22: Lab2.1 | J22: - Thực hành Lab2.1 | K22: - Thực hành Lab2.1
J23: * Phân bổ thời gian: | K23: * Thực hiện các công việc:
J24: + (1 giờ): Học theo sự giảng dạy của giảng viên | K24: + Hướng dẫn sinh viên thực hiện asm qua từng bài học
J25: + (1 giờ): Thực hành hoặc thảo luận tình huống | K25: + Thuyết giảng theo slide bài giảng
J26: + (30 phút): Xem bài thuyết giảng của giảng viên qua video trên LMS/CMS | K26: + Hướng dẫn, ôn bài, chỉ rõ những điểm quan trọng trong video
J27: + (1 giờ 30 phút): Thực hiện assignment
A28: 4 | B28: Slide 2.2 - Các khái niệm cơ bản; Lab 2.2 | C28: Offline | D28: CLO2.2 | E28: TU | F28: Slide2.2, | H28: Slide2.2, | J28: - Review Slide 2.1 | K28: - Review Slide 2.1
B29: - Toán tử trong lập trình | F29: Online 2.2, | H29: Online 2.2, | J29: - Slide2.2 | K29: - Slide2.2
B30: - Xây dựng biểu thức | F30: Lab2.2, Quiz1 | H30: Lab2.2, Quiz1 | J30: - Thực hành Lab2.2 | K30: - Thực hành Lab2.2
J31: - Nộp Lab1(Lab11-Lab22) | K31: - Nộp Lab1(Lab11-Lab22)
J32: * Phân bổ thời gian: | K32: * Thực hiện các công việc:
J33: + (1 giờ): Học theo sự giảng dạy của giảng viên | K33: + Hướng dẫn sinh viên thực hiện asm qua từng bài học
J34: + (1 giờ): Thực hành hoặc thảo luận tình huống | K34: + Hướng dẫn, kiểm soát và chấm bài
J35: + (15 phút): Thực hiện trắc nghiệm trên LMS/CMS | K35: + Thuyết giảng theo slide bài giảng
J36: + (30 phút): Xem bài thuyết giảng của giảng viên qua video trên LMS/CMS | K36: + Hướng dẫn, ôn bài, chỉ rõ những điểm quan trọng trong video
J37: + (1 giờ 30 phút): Thực hiện assignment
A38: 5 | B38: Slide 3.1 - Câu lệnh điều kiện; Lab 3.1 | C38: Offline | D38: CLO3.1 | E38: TU | F38: Slide3.1, | H38: Slide3.1, | J38: - Review Slide 2.2, | K38: - Review Slide 2.2,
B39: - Câu lệnh điều kiện If | F39: Online 3.1, | H39: Online 3.1, | J39: - Slide3.1 | K39: - Slide3.1
F40: Lab3.1 | H40: Lab3.1 | J40: - Thực hành Lab3.1 | K40: - Thực hành Lab3.1
J41: * Phân bổ thời gian: | K41: * Thực hiện các công việc:
...

Sheet Grading structure
A1: Category | B1: Type | C1: Part | D1: Weight | E1: Completion Criteria | F1: Duration | G1: CLO | H1: Question Type | I1: No Question | J1: Knowledge and Skill | K1: Grading Guide | L1: Note
A2: Assignment | B2: On-going | C2: 2 | D2: 20.0%
A3: Bài học online | B3: On-going | C3: 1 | D3: .0% | E3: 10 | G3: All CLOs | H3: Trắc nghiệm | K3: Học theo tiến độ bài học online. Điểm tính theo tỷ lệ hoàn thành bài học Online (100%)
A4: Đánh giá Assignment GĐ 1 | B4: On-going | C4: 1 | D4: 10.0% | J4: Nội dung trong các sách giáo trình của các môn học trước đó | K4: SV nộp bài để giáo viên chấm
K5: (thời hạn: cuối giờ hoặc cuối ngày, hoặc giảng viên quy định phù hợp với thời gian học của lớp)
A6: Đánh giá Assignment GĐ 2 | B6: On-going | C6: 1 | D6: 10.0% | J6: Nội dung trong các sách giáo trình của các môn học trước đó | K6: SV nộp bài để giáo viên chấm
K7: (thời hạn: cuối giờ hoặc cuối ngày, hoặc giảng viên quy định phù hợp với thời gian học của lớp)
A8: Lab | B8: On-going | C8: 4 | D8: 20.0%
A9: Lab1 | B9: On-going | C9: 1 | D9: 5.0% | G9: CLO1, CLO2 | H9: Tình huống | I9: 4 bài | J9: Slide1-2 | K9: Giảng viên chấm bằng tay tại lớp hoặc download từ LMS để chấm
A10: Lab2 | B10: On-going | C10: 1 | D10: 5.0% | G10: CLO3, CLO4 | H10: Tình huống | I10: 4 bài | J10: Slide3-4 | K10: Giảng viên chấm bằng tay tại lớp hoặc download từ LMS để chấm
A11: Lab3 | B11: On-going | C11: 1 | D11: 5.0% | G11: CLO4, CLO5 | H11: Tình huống | I11: 4 bài | J11: Slide5-6 | K11: Giảng viên chấm bằng tay tại lớp hoặc download từ LMS để chấm
A12: Lab4 | B12: On-going | C12: 1 | D12: 5.0% | G12: CLO6, CLO7 | H12: Tình huống | I12: 4 bài | J12: Slide7-8 | K12: Giảng viên chấm bằng tay tại lớp hoặc download từ LMS để chấm
A13: Quiz | B13: On-going | C13: 4 | D13: 20.0%
A14: Quiz 1 | B14: On-going | C14: 1 | D14: 5.0% | F14: 10 phút | G14: CLO1, CLO2 | H14: Trắc nghiệm | I14: 15 | J14: Slide 1,2 | K14: Tổ chức tự động trên LMS | L14: GV phải điều chỉnh thời gian bắt đầu cho bài quiz
A15: Quiz 2 | B15: On-going | C15: 1 | D15: 5.0% | F15: 10 phút | G15: CLO3, CLO4 | H15: Trắc nghiệm | I15: 15 | J15: Slide 3,4 | K15: Tổ chức tự động trên LMS | L15: GV phải điều chỉnh thời gian bắt đầu cho bài quiz
A16: Quiz 3 | B16: On-going | C16: 1 | D16: 5.0% | F16: 10 phút | G16: CLO5, CLO6 | H16: Trắc nghiệm | I16: 15 | J16: Slide 5,6 | K16: Tổ chức tự động trên LMS | L16: GV phải điều chỉnh thời gian bắt đầu cho bài quiz
A17: Quiz 4 | B17: On-going | C17: 1 | D17: 5.0% | F17: 10 phút | G17: CLO6, CLO7 | H17: Trắc nghiệm | I17: 15 | J17: Slide 7,8 | K17: Tổ chức tự động trên LMS | L17: GV phải điều chỉnh thời gian bắt đầu cho bài quiz
A18: Bảo vệ Assignment | B18: Final Exam | C18: 1 | D18: 40.0% | E18: 5 | F18: 2h | G18: All CLOs | H18: Sản phẩm, Slide, Document, Đề thi | I18: Assignment | J18: Toàn bộ kiến thức, kỹ năng và thái độ được yêu cầu trong assignment | K18: * Hội đồng bảo vệ gồm 2 giảng viên (đứng lớp và phản biện) | L18: Sinh viên nộp sản phẩm đúng nơi quy định. Giảng viên hội đồng tải sản phẩm của sinh viên và xem trước ngày bảo vệ
K19: * Trước buổi bảo vệ: Giảng viên chấm document, slide PowerPoint (nếu thuyết trình) và xem qua sản phẩm hoàn chỉnh do sinh viên nộp
K20: * Tại buổi bảo vệ: Trình bày theo nhóm hoặc cá nhân. Hội đồng phỏng vấn từng sinh viên.

Sheet Deadline
B1: 2 | C1: 3 | D1: 4 | E1: 5 | F1: 6 | G1: 7 | H1: 8 | I1: 9 | J1: 10 | K1: 11
A2: # | B2: Ngày | C2: Ca học | D2: Khu | E2: Phòng | F2: Lớp | G2: Giảng viên | H2: Mã môn | I2: Tên môn | J2: Deadline | K2: Nhiệm vụ
A3: 1 | B3: =IFERROR(VLOOKUP($A3,'Lịch AP'!$A:$J,B$1,0),"") -> 45965 | C3: =IFERROR(VLOOKUP($A3,'Lịch AP'!$A:$J,C$1,0),"") -> 1 | D3: =IFERROR(VLOOKUP($A3,'Lịch AP'!$A:$J,D$1,0),"") -> PMQT | E3: =IFERROR(VLOOKUP($A3,'Lịch AP'!$A:$J,E$1,0),"") -> T1006 (Nha T) | F3: =IFERROR(VLOOKUP($A3,'Lịch AP'!$A:$J,F$1,0),"") -> SD21301 | G3: =IFERROR(VLOOKUP($A3,'Lịch AP'!$A:$J,G$1,0),"") -> baytt | H3: =IFERROR(VLOOKUP($A3,'Lịch AP'!$A:$J,H$1,0),"") -> COM108 | I3: =IFERROR(VLOOKUP($A3,'Lịch AP'!$A:$J,I$1,0),"") -> Nhập môn lập trình
A4: 2 | B4: =IFERROR(VLOOKUP($A4,'Lịch AP'!$A:$J,B$1,0),"") -> 45967 | C4: =IFERROR(VLOOKUP($A4,'Lịch AP'!$A:$J,C$1,0),"") -> 1 | D4: =IFERROR(VLOOKUP($A4,'Lịch AP'!$A:$J,D$1,0),"") -> PMQT | E4: =IFERROR(VLOOKUP($A4,'Lịch AP'!$A:$J,E$1,0),"") -> T1006 (Nha T) | F4: =IFERROR(VLOOKUP($A4,'Lịch AP'!$A:$J,F$1,0),"") -> SD21301 | G4: =IFERROR(VLOOKUP($A4,'Lịch AP'!$A:$J,G$1,0),"") -> baytt | H4: =IFERROR(VLOOKUP($A4,'Lịch AP'!$A:$J,H$1,0),"") -> COM108 | I4: =IFERROR(VLOOKUP($A4,'Lịch AP'!$A:$J,I$1,0),"") -> Nhập môn lập trình
B5: =IFERROR(VLOOKUP($A5,'Lịch AP'!$A:$J,B$1,0),"") | C5: =IFERROR(VLOOKUP($A5,'Lịch AP'!$A:$J,C$1,0),"") | D5: =IFERROR(VLOOKUP($A5,'Lịch AP'!$A:$J,D$1,0),"") | E5: =IFERROR(VLOOKUP($A5,'Lịch AP'!$A:$J,E$1,0),"") | F5: =IFERROR(VLOOKUP($A5,'Lịch AP'!$A:$J,F$1,0),"") | G5: =IFERROR(VLOOKUP($A5,'Lịch AP'!$A:$J,G$1,0),"") | H5: =IFERROR(VLOOKUP($A5,'Lịch AP'!$A:$J,H$1,0),"") | I5: =IFERROR(VLOOKUP($A5,'Lịch AP'!$A:$J,I$1,0),"") | J5: =B7-1 -> 45968 | K5: Lab 1
B6: =IFERROR(VLOOKUP($A6,'Lịch AP'!$A:$J,B$1,0),"") | C6: =IFERROR(VLOOKUP($A6,'Lịch AP'!$A:$J,C$1,0),"") | D6: =IFERROR(VLOOKUP($A6,'Lịch AP'!$A:$J,D$1,0),"") | E6: =IFERROR(VLOOKUP($A6,'Lịch AP'!$A:$J,E$1,0),"") | F6: =IFERROR(VLOOKUP($A6,'Lịch AP'!$A:$J,F$1,0),"") | G6: =IFERROR(VLOOKUP($A6,'Lịch AP'!$A:$J,G$1,0),"") | H6: =IFERROR(VLOOKUP($A6,'Lịch AP'!$A:$J,H$1,0),"") | I6: =IFERROR(VLOOKUP($A6,'Lịch AP'!$A:$J,I$1,0),"")
A7: 3 | B7: =IFERROR(VLOOKUP($A7,'Lịch AP'!$A:$J,B$1,0),"") -> 45969 | C7: =IFERROR(VLOOKUP($A7,'Lịch AP'!$A:$J,C$1,0),"") -> 1 | D7: =IFERROR(VLOOKUP($A7,'Lịch AP'!$A:$J,D$1,0),"") -> PMQT | E7: =IFERROR(VLOOKUP($A7,'Lịch AP'!$A:$J,E$1,0),"") -> T1006 (Nha T) | F7: =IFERROR(VLOOKUP($A7,'Lịch AP'!$A:$J,F$1,0),"") -> SD21301 | G7: =IFERROR(VLOOKUP($A7,'Lịch AP'!$A:$J,G$1,0),"") -> baytt | H7: =IFERROR(VLOOKUP($A7,'Lịch AP'!$A:$J,H$1,0),"") -> COM108 | I7: =IFERROR(VLOOKUP($A7,'Lịch AP'!$A:$J,I$1,0),"") -> Nhập môn lập trình
A8: 4 | B8: =IFERROR(VLOOKUP($A8,'Lịch AP'!$A:$J,B$1,0),"") -> 45972 | C8: =IFERROR(VLOOKUP($A8,'Lịch AP'!$A:$J,C$1,0),"") -> 1 | D8: =IFERROR(VLOOKUP($A8,'Lịch AP'!$A:$J,D$1,0),"") -> PMQT | E8: =IFERROR(VLOOKUP($A8,'Lịch AP'!$A:$J,E$1,0),"") -> T1006 (Nha T) | F8: =IFERROR(VLOOKUP($A8,'Lịch AP'!$A:$J,F$1,0),"") -> SD21301 | G8: =IFERROR(VLOOKUP($A8,'Lịch AP'!$A:$J,G$1,0),"") -> baytt | H8: =IFERROR(VLOOKUP($A8,'Lịch AP'!$A:$J,H$1,0),"") -> COM108 | I8: =IFERROR(VLOOKUP($A8,'Lịch AP'!$A:$J,I$1,0),"") -> Nhập môn lập trình
B9: =IFERROR(VLOOKUP($A9,'Lịch AP'!$A:$J,B$1,0),"") | C9: =IFERROR(VLOOKUP($A9,'Lịch AP'!$A:$J,C$1,0),"") | D9: =IFERROR(VLOOKUP($A9,'Lịch AP'!$A:$J,D$1,0),"") | E9: =IFERROR(VLOOKUP($A9,'Lịch AP'!$A:$J,E$1,0),"") | F9: =IFERROR(VLOOKUP($A9,'Lịch AP'!$A:$J,F$1,0),"") | G9: =IFERROR(VLOOKUP($A9,'Lịch AP'!$A:$J,G$1,0),"") | H9: =IFERROR(VLOOKUP($A9,'Lịch AP'!$A:$J,H$1,0),"") | I9: =IFERROR(VLOOKUP($A9,'Lịch AP'!$A:$J,I$1,0),"") | J9: =B11-1 -> 45973 | K9: Lab 2, Quiz 1
B10: =IFERROR(VLOOKUP($A10,'Lịch AP'!$A:$J,B$1,0),"") | C10: =IFERROR(VLOOKUP($A10,'Lịch AP'!$A:$J,C$1,0),"") | D10: =IFERROR(VLOOKUP($A10,'Lịch AP'!$A:$J,D$1,0),"") | E10: =IFERROR(VLOOKUP($A10,'Lịch AP'!$A:$J,E$1,0),"") | F10: =IFERROR(VLOOKUP($A10,'Lịch AP'!$A:$J,F$1,0),"") | G10: =IFERROR(VLOOKUP($A10,'Lịch AP'!$A:$J,G$1,0),"") | H10: =IFERROR(VLOOKUP($A10,'Lịch AP'!$A:$J,H$1,0),"") | I10: =IFERROR(VLOOKUP($A10,'Lịch AP'!$A:$J,I$1,0),"")
A11: 5 | B11: =IFERROR(VLOOKUP($A11,'Lịch AP'!$A:$J,B$1,0),"") -> 45974 | C11: =IFERROR(VLOOKUP($A11,'Lịch AP'!$A:$J,C$1,0),"") -> 1 | D11: =IFERROR(VLOOKUP($A11,'Lịch AP'!$A:$J,D$1,0),"") -> PMQT | E11: =IFERROR(VLOOKUP($A11,'Lịch AP'!$A:$J,E$1,0),"") -> T1006 (Nha T) | F11: =IFERROR(VLOOKUP($A11,'Lịch AP'!$A:$J,F$1,0),"") -> SD21301 | G11: =IFERROR(VLOOKUP($A11,'Lịch AP'!$A:$J,G$1,0),"") -> baytt | H11: =IFERROR(VLOOKUP($A11,'Lịch AP'!$A:$J,H$1,0),"") -> COM108 | I11: =IFERROR(VLOOKUP($A11,'Lịch AP'!$A:$J,I$1,0),"") -> Nhập môn lập trình
A12: 6 | B12: =IFERROR(VLOOKUP($A12,'Lịch AP'!$A:$J,B$1,0),"") -> 45976 | C12: =IFERROR(VLOOKUP($A12,'Lịch AP'!$A:$J,C$1,0),"") -> 1 | D12: =IFERROR(VLOOKUP($A12,'Lịch AP'!$A:$J,D$1,0),"") -> PMQT | E12: =IFERROR(VLOOKUP($A12,'Lịch AP'!$A:$J,E$1,0),"") -> T1006 (Nha T) | F12: =IFERROR(VLOOKUP($A12,'Lịch AP'!$A:$J,F$1,0),"") -> SD21301 | G12: =IFERROR(VLOOKUP($A12,'Lịch AP'!$A:$J,G$1,0),"") -> baytt | H12: =IFERROR(VLOOKUP($A12,'Lịch AP'!$A:$J,H$1,0),"") -> COM108 | I12: =IFERROR(VLOOKUP($A12,'Lịch AP'!$A:$J,I$1,0),"") -> Nhập môn lập trình
B13: =IFERROR(VLOOKUP($A13,'Lịch AP'!$A:$J,B$1,0),"") | C13: =IFERROR(VLOOKUP($A13,'Lịch AP'!$A:$J,C$1,0),"") | D13: =IFERROR(VLOOKUP($A13,'Lịch AP'!$A:$J,D$1,0),"") | E13: =IFERROR(VLOOKUP($A13,'Lịch AP'!$A:$J,E$1,0),"") | F13: =IFERROR(VLOOKUP($A13,'Lịch AP'!$A:$J,F$1,0),"") | G13: =IFERROR(VLOOKUP($A13,'Lịch AP'!$A:$J,G$1,0),"") | H13: =IFERROR(VLOOKUP($A13,'Lịch AP'!$A:$J,H$1,0),"") | I13: =IFERROR(VLOOKUP($A13,'Lịch AP'!$A:$J,I$1,0),"") | J13: =B15-1 -> 45978 | K13: Lab 3
B14: =IFERROR(VLOOKUP($A14,'Lịch AP'!$A:$J,B$1,0),"") | C14: =IFERROR(VLOOKUP($A14,'Lịch AP'!$A:$J,C$1,0),"") | D14: =IFERROR(VLOOKUP($A14,'Lịch AP'!$A:$J,D$1,0),"") | E14: =IFERROR(VLOOKUP($A14,'Lịch AP'!$A:$J,E$1,0),"") | F14: =IFERROR(VLOOKUP($A14,'Lịch AP'!$A:$J,F$1,0),"") | G14: =IFERROR(VLOOKUP($A14,'Lịch AP'!$A:$J,G$1,0),"") | H14: =IFERROR(VLOOKUP($A14,'Lịch AP'!$A:$J,H$1,0),"") | I14: =IFERROR(VLOOKUP($A14,'Lịch AP'!$A:$J,I$1,0),"")
A15: 7 | B15: =IFERROR(VLOOKUP($A15,'Lịch AP'!$A:$J,B$1,0),"") -> 45979 | C15: =IFERROR(VLOOKUP($A15,'Lịch AP'!$A:$J,C$1,0),"") -> 1 | D15: =IFERROR(VLOOKUP($A15,'Lịch AP'!$A:$J,D$1,0),"") -> PMQT | E15: =IFERROR(VLOOKUP($A15,'Lịch AP'!$A:$J,E$1,0),"") -> T1006 (Nha T) | F15: =IFERROR(VLOOKUP($A15,'Lịch AP'!$A:$J,F$1,0),"") -> SD21301 | G15: =IFERROR(VLOOKUP($A15,'Lịch AP'!$A:$J,G$1,0),"") -> baytt | H15: =IFERROR(VLOOKUP($A15,'Lịch AP'!$A:$J,H$1,0),"") -> COM108 | I15: =IFERROR(VLOOKUP($A15,'Lịch AP'!$A:$J,I$1,0),"") -> Nhập môn lập trình
A16: 8 | B16: =IFERROR(VLOOKUP($A16,'Lịch AP'!$A:$J,B$1,0),"") -> 45981 | C16: =IFERROR(VLOOKUP($A16,'Lịch AP'!$A:$J,C$1,0),"") -> 1 | D16: =IFERROR(VLOOKUP($A16,'Lịch AP'!$A:$J,D$1,0),"") -> PMQT | E16: =IFERROR(VLOOKUP($A16,'Lịch AP'!$A:$J,E$1,0),"") -> T1006 (Nha T) | F16: =IFERROR(VLOOKUP($A16,'Lịch AP'!$A:$J,F$1,0),"") -> SD21301 | G16: =IFERROR(VLOOKUP($A16,'Lịch AP'!$A:$J,G$1,0),"") -> baytt | H16: =IFERROR(VLOOKUP($A16,'Lịch AP'!$A:$J,H$1,0),"") -> COM108 | I16: =IFERROR(VLOOKUP($A16,'Lịch AP'!$A:$J,I$1,0),"") -> Nhập môn lập trình
B17: =IFERROR(VLOOKUP($A17,'Lịch AP'!$A:$J,B$1,0),"") | C17: =IFERROR(VLOOKUP($A17,'Lịch AP'!$A:$J,C$1,0),"") | D17: =IFERROR(VLOOKUP($A17,'Lịch AP'!$A:$J,D$1,0),"") | E17: =IFERROR(VLOOKUP($A17,'Lịch AP'!$A:$J,E$1,0),"") | F17: =IFERROR(VLOOKUP($A17,'Lịch AP'!$A:$J,F$1,0),"") | G17: =IFERROR(VLOOKUP($A17,'Lịch AP'!$A:$J,G$1,0),"") | H17: =IFERROR(VLOOKUP($A17,'Lịch AP'!$A:$J,H$1,0),"") | I17: =IFERROR(VLOOKUP($A17,'Lịch AP'!$A:$J,I$1,0),"") | J17: =B19-1 -> 45982 | K17: Lab 4, Quiz 2 + ASM 1
B18: =IFERROR(VLOOKUP($A18,'Lịch AP'!$A:$J,B$1,0),"") | C18: =IFERROR(VLOOKUP($A18,'Lịch AP'!$A:$J,C$1,0),"") | D18: =IFERROR(VLOOKUP($A18,'Lịch AP'!$A:$J,D$1,0),"") | E18: =IFERROR(VLOOKUP($A18,'Lịch AP'!$A:$J,E$1,0),"") | F18: =IFERROR(VLOOKUP($A18,'Lịch AP'!$A:$J,F$1,0),"") | G18: =IFERROR(VLOOKUP($A18,'Lịch AP'!$A:$J,G$1,0),"") | H18: =IFERROR(VLOOKUP($A18,'Lịch AP'!$A:$J,H$1,0),"") | I18: =IFERROR(VLOOKUP($A18,'Lịch AP'!$A:$J,I$1,0),"")
A19: 9 | B19: =IFERROR(VLOOKUP($A19,'Lịch AP'!$A:$J,B$1,0),"") -> 45983 | C19: =IFERROR(VLOOKUP($A19,'Lịch AP'!$A:$J,C$1,0),"") -> 1 | D19: =IFERROR(VLOOKUP($A19,'Lịch AP'!$A:$J,D$1,0),"") -> PMQT | E19: =IFERROR(VLOOKUP($A19,'Lịch AP'!$A:$J,E$1,0),"") -> T1006 (Nha T) | F19: =IFERROR(VLOOKUP($A19,'Lịch AP'!$A:$J,F$1,0),"") -> SD21301 | G19: =IFERROR(VLOOKUP($A19,'Lịch AP'!$A:$J,G$1,0),"") -> baytt | H19: =IFERROR(VLOOKUP($A19,'Lịch AP'!$A:$J,H$1,0),"") -> COM108 | I19: =IFERROR(VLOOKUP($A19,'Lịch AP'!$A:$J,I$1,0),"") -> Nhập môn lập trình
A20: 10 | B20: =IFERROR(VLOOKUP($A20,'Lịch AP'!$A:$J,B$1,0),"") -> 45986 | C20: =IFERROR(VLOOKUP($A20,'Lịch AP'!$A:$J,C$1,0),"") -> 1 | D20: =IFERROR(VLOOKUP($A20,'Lịch AP'!$A:$J,D$1,0),"") -> PMQT | E20: =IFERROR(VLOOKUP($A20,'Lịch AP'!$A:$J,E$1,0),"") -> T1006 (Nha T) | F20: =IFERROR(VLOOKUP($A20,'Lịch AP'!$A:$J,F$1,0),"") -> SD21301 | G20: =IFERROR(VLOOKUP($A20,'Lịch AP'!$A:$J,G$1,0),"") -> baytt | H20: =IFERROR(VLOOKUP($A20,'Lịch AP'!$A:$J,H$1,0),"") -> COM108 | I20: =IFERROR(VLOOKUP($A20,'Lịch AP'!$A:$J,I$1,0),"") -> Nhập môn lập trình
B21: =IFERROR(VLOOKUP($A21,'Lịch AP'!$A:$J,B$1,0),"") | C21: =IFERROR(VLOOKUP($A21,'Lịch AP'!$A:$J,C$1,0),"") | D21: =IFERROR(VLOOKUP($A21,'Lịch AP'!$A:$J,D$1,0),"") | E21: =IFERROR(VLOOKUP($A21,'Lịch AP'!$A:$J,E$1,0),"") | F21: =IFERROR(VLOOKUP($A21,'Lịch AP'!$A:$J,F$1,0),"") | G21: =IFERROR(VLOOKUP($A21,'Lịch AP'!$A:$J,G$1,0),"") | H21: =IFERROR(VLOOKUP($A21,'Lịch AP'!$A:$J,H$1,0),"") | I21: =IFERROR(VLOOKUP($A21,'Lịch AP'!$A:$J,I$1,0),"") | J21: =B23-1 -> 45987 | K21: Lab 5
B22: =IFERROR(VLOOKUP($A22,'Lịch AP'!$A:$J,B$1,0),"") | C22: =IFERROR(VLOOKUP($A22,'Lịch AP'!$A:$J,C$1,0),"") | D22: =IFERROR(VLOOKUP($A22,'Lịch AP'!$A:$J,D$1,0),"") | E22: =IFERROR(VLOOKUP($A22,'Lịch AP'!$A:$J,E$1,0),"") | F22: =IFERROR(VLOOKUP($A22,'Lịch AP'!$A:$J,F$1,0),"") | G22: =IFERROR(VLOOKUP($A22,'Lịch AP'!$A:$J,G$1,0),"") | H22: =IFERROR(VLOOKUP($A22,'Lịch AP'!$A:$J,H$1,0),"") | I22: =IFERROR(VLOOKUP($A22,'Lịch AP'!$A:$J,I$1,0),"")
A23: 11 | B23: =IFERROR(VLOOKUP($A23,'Lịch AP'!$A:$J,B$1,0),"") -> 45988 | C23: =IFERROR(VLOOKUP($A23,'Lịch AP'!$A:$J,C$1,0),"") -> 1 | D23: =IFERROR(VLOOKUP($A23,'Lịch AP'!$A:$J,D$1,0),"") -> PMQT | E23: =IFERROR(VLOOKUP($A23,'Lịch AP'!$A:$J,E$1,0),"") -> T1006 (Nha T) | F23: =IFERROR(VLOOKUP($A23,'Lịch AP'!$A:$J,F$1,0),"") -> SD21301 | G23: =IFERROR(VLOOKUP($A23,'Lịch AP'!$A:$J,G$1,0),"") -> baytt | H23: =IFERROR(VLOOKUP($A23,'Lịch AP'!$A:$J,H$1,0),"") -> COM108 | I23: =IFERROR(VLOOKUP($A23,'Lịch AP'!$A:$J,I$1,0),"") -> Nhập môn lập trình
A24: 12 | B24: =IFERROR(VLOOKUP($A24,'Lịch AP'!$A:$J,B$1,0),"") -> 45990 | C24: =IFERROR(VLOOKUP($A24,'Lịch AP'!$A:$J,C$1,0),"") -> 1 | D24: =IFERROR(VLOOKUP($A24,'Lịch AP'!$A:$J,D$1,0),"") -> PMQT | E24: =IFERROR(VLOOKUP($A24,'Lịch AP'!$A:$J,E$1,0),"") -> T1006 (Nha T) | F24: =IFERROR(VLOOKUP($A24,'Lịch AP'!$A:$J,F$1,0),"") -> SD21301 | G24: =IFERROR(VLOOKUP($A24,'Lịch AP'!$A:$J,G$1,0),"") -> baytt | H24: =IFERROR(VLOOKUP($A24,'Lịch AP'!$A:$J,H$1,0),"") -> COM108 | I24: =IFERROR(VLOOKUP($A24,'Lịch AP'!$A:$J,I$1,0),"") -> Nhập môn lập trình
B25: =IFERROR(VLOOKUP($A25,'Lịch AP'!$A:$J,B$1,0),"") | C25: =IFERROR(VLOOKUP($A25,'Lịch AP'!$A:$J,C$1,0),"") | D25: =IFERROR(VLOOKUP($A25,'Lịch AP'!$A:$J,D$1,0),"") | E25: =IFERROR(VLOOKUP($A25,'Lịch AP'!$A:$J,E$1,0),"") | F25: =IFERROR(VLOOKUP($A25,'Lịch AP'!$A:$J,F$1,0),"") | G25: =IFERROR(VLOOKUP($A25,'Lịch AP'!$A:$J,G$1,0),"") | H25: =IFERROR(VLOOKUP($A25,'Lịch AP'!$A:$J,H$1,0),"") | I25: =IFERROR(VLOOKUP($A25,'Lịch AP'!$A:$J,I$1,0),"") | J25: =B27-1 -> 45992 | K25: Lab 6,7 và Quiz 3
B26: =IFERROR(VLOOKUP($A26,'Lịch AP'!$A:$J,B$1,0),"") | C26: =IFERROR(VLOOKUP($A26,'Lịch AP'!$A:$J,C$1,0),"") | D26: =IFERROR(VLOOKUP($A26,'Lịch AP'!$A:$J,D$1,0),"") | E26: =IFERROR(VLOOKUP($A26,'Lịch AP'!$A:$J,E$1,0),"") | F26: =IFERROR(VLOOKUP($A26,'Lịch AP'!$A:$J,F$1,0),"") | G26: =IFERROR(VLOOKUP($A26,'Lịch AP'!$A:$J,G$1,0),"") | H26: =IFERROR(VLOOKUP($A26,'Lịch AP'!$A:$J,H$1,0),"") | I26: =IFERROR(VLOOKUP($A26,'Lịch AP'!$A:$J,I$1,0),"")
A27: 13 | B27: =IFERROR(VLOOKUP($A27,'Lịch AP'!$A:$J,B$1,0),"") -> 45993 | C27: =IFERROR(VLOOKUP($A27,'Lịch AP'!$A:$J,C$1,0),"") -> 1 | D27: =IFERROR(VLOOKUP($A27,'Lịch AP'!$A:$J,D$1,0),"") -> PMQT | E27: =IFERROR(VLOOKUP($A27,'Lịch AP'!$A:$J,E$1,0),"") -> T1006 (Nha T) | F27: =IFERROR(VLOOKUP($A27,'Lịch AP'!$A:$J,F$1,0),"") -> SD21301 | G27: =IFERROR(VLOOKUP($A27,'Lịch AP'!$A:$J,G$1,0),"") -> baytt | H27: =IFERROR(VLOOKUP($A27,'Lịch AP'!$A:$J,H$1,0),"") -> COM108 | I27: =IFERROR(VLOOKUP($A27,'Lịch AP'!$A:$J,I$1,0),"") -> Nhập môn lập trình
A28: 14 | B28: =IFERROR(VLOOKUP($A28,'Lịch AP'!$A:$J,B$1,0),"") -> 45995 | C28: =IFERROR(VLOOKUP($A28,'Lịch AP'!$A:$J,C$1,0),"") -> 1 | D28: =IFERROR(VLOOKUP($A28,'Lịch AP'!$A:$J,D$1,0),"") -> PMQT | E28: =IFERROR(VLOOKUP($A28,'Lịch AP'!$A:$J,E$1,0),"") -> T1006 (Nha T) | F28: =IFERROR(VLOOKUP($A28,'Lịch AP'!$A:$J,F$1,0),"") -> SD21301 | G28: =IFERROR(VLOOKUP($A28,'Lịch AP'!$A:$J,G$1,0),"") -> baytt | H28: =IFERROR(VLOOKUP($A28,'Lịch AP'!$A:$J,H$1,0),"") -> COM108 | I28: =IFERROR(VLOOKUP($A28,'Lịch AP'!$A:$J,I$1,0),"") -> Nhập môn lập trình
B29: =IFERROR(VLOOKUP($A29,'Lịch AP'!$A:$J,B$1,0),"") | C29: =IFERROR(VLOOKUP($A29,'Lịch AP'!$A:$J,C$1,0),"") | D29: =IFERROR(VLOOKUP($A29,'Lịch AP'!$A:$J,D$1,0),"") | E29: =IFERROR(VLOOKUP($A29,'Lịch AP'!$A:$J,E$1,0),"") | F29: =IFERROR(VLOOKUP($A29,'Lịch AP'!$A:$J,F$1,0),"") | G29: =IFERROR(VLOOKUP($A29,'Lịch AP'!$A:$J,G$1,0),"") | H29: =IFERROR(VLOOKUP($A29,'Lịch AP'!$A:$J,H$1,0),"") | I29: =IFERROR(VLOOKUP($A29,'Lịch AP'!$A:$J,I$1,0),"") | J29: =B31-1 -> 45996 | K29: Lab 8, Quiz 4 +ASM 2
B30: =IFERROR(VLOOKUP($A30,'Lịch AP'!$A:$J,B$1,0),"") | C30: =IFERROR(VLOOKUP($A30,'Lịch AP'!$A:$J,C$1,0),"") | D30: =IFERROR(VLOOKUP($A30,'Lịch AP'!$A:$J,D$1,0),"") | E30: =IFERROR(VLOOKUP($A30,'Lịch AP'!$A:$J,E$1,0),"") | F30: =IFERROR(VLOOKUP($A30,'Lịch AP'!$A:$J,F$1,0),"") | G30: =IFERROR(VLOOKUP($A30,'Lịch AP'!$A:$J,G$1,0),"") | H30: =IFERROR(VLOOKUP($A30,'Lịch AP'!$A:$J,H$1,0),"") | I30: =IFERROR(VLOOKUP($A30,'Lịch AP'!$A:$J,I$1,0),"")
A31: 15 | B31: =IFERROR(VLOOKUP($A31,'Lịch AP'!$A:$J,B$1,0),"") -> 45997 | C31: =IFERROR(VLOOKUP($A31,'Lịch AP'!$A:$J,C$1,0),"") -> 1 | D31: =IFERROR(VLOOKUP($A31,'Lịch AP'!$A:$J,D$1,0),"") -> PMQT | E31: =IFERROR(VLOOKUP($A31,'Lịch AP'!$A:$J,E$1,0),"") -> T1006 (Nha T) | F31: =IFERROR(VLOOKUP($A31,'Lịch AP'!$A:$J,F$1,0),"") -> SD21301 | G31: =IFERROR(VLOOKUP($A31,'Lịch AP'!$A:$J,G$1,0),"") -> baytt | H31: =IFERROR(VLOOKUP($A31,'Lịch AP'!$A:$J,H$1,0),"") -> COM108 | I31: =IFERROR(VLOOKUP($A31,'Lịch AP'!$A:$J,I$1,0),"") -> Nhập môn lập trình
A32: 16 | B32: =IFERROR(VLOOKUP($A32,'Lịch AP'!$A:$J,B$1,0),"") -> 46000 | C32: =IFERROR(VLOOKUP($A32,'Lịch AP'!$A:$J,C$1,0),"") -> 1 | D32: =IFERROR(VLOOKUP($A32,'Lịch AP'!$A:$J,D$1,0),"") -> PMQT | E32: =IFERROR(VLOOKUP($A32,'Lịch AP'!$A:$J,E$1,0),"") -> T1006 (Nha T) | F32: =IFERROR(VLOOKUP($A32,'Lịch AP'!$A:$J,F$1,0),"") -> SD21301 | G32: =IFERROR(VLOOKUP($A32,'Lịch AP'!$A:$J,G$1,0),"") -> baytt | H32: =IFERROR(VLOOKUP($A32,'Lịch AP'!$A:$J,H$1,0),"") -> COM108 | I32: =IFERROR(VLOOKUP($A32,'Lịch AP'!$A:$J,I$1,0),"") -> Nhập môn lập trình
A33: 17 | B33: =IFERROR(VLOOKUP($A33,'Lịch AP'!$A:$J,B$1,0),"") -> 46002 | C33: =IFERROR(VLOOKUP($A33,'Lịch AP'!$A:$J,C$1,0),"") -> 1 | D33: =IFERROR(VLOOKUP($A33,'Lịch AP'!$A:$J,D$1,0),"") -> PMQT | E33: =IFERROR(VLOOKUP($A33,'Lịch AP'!$A:$J,E$1,0),"") -> T1006 (Nha T) | F33: =IFERROR(VLOOKUP($A33,'Lịch AP'!$A:$J,F$1,0),"") -> SD21301 | G33: =IFERROR(VLOOKUP($A33,'Lịch AP'!$A:$J,G$1,0),"") -> baytt | H33: =IFERROR(VLOOKUP($A33,'Lịch AP'!$A:$J,H$1,0),"") -> COM108 | I33: =IFERROR(VLOOKUP($A33,'Lịch AP'!$A:$J,I$1,0),"") -> Nhập môn lập trình
B34: =IFERROR(VLOOKUP($A34,'Lịch AP'!$A:$J,B$1,0),"") | C34: =IFERROR(VLOOKUP($A34,'Lịch AP'!$A:$J,C$1,0),"") | D34: =IFERROR(VLOOKUP($A34,'Lịch AP'!$A:$J,D$1,0),"") | E34: =IFERROR(VLOOKUP($A34,'Lịch AP'!$A:$J,E$1,0),"") | F34: =IFERROR(VLOOKUP($A34,'Lịch AP'!$A:$J,F$1,0),"") | G34: =IFERROR(VLOOKUP($A34,'Lịch AP'!$A:$J,G$1,0),"") | H34: =IFERROR(VLOOKUP($A34,'Lịch AP'!$A:$J,H$1,0),"") | I34: =IFERROR(VLOOKUP($A34,'Lịch AP'!$A:$J,I$1,0),"") | J34: =B35-1 -> 46003 | K34: ASM 2(Bổ sung)
A35: 18 | B35: =IFERROR(VLOOKUP($A35,'Lịch AP'!$A:$J,B$1,0),"") -> 46004 | C35: =IFERROR(VLOOKUP($A35,'Lịch AP'!$A:$J,C$1,0),"") -> 1 | D35: =IFERROR(VLOOKUP($A35,'Lịch AP'!$A:$J,D$1,0),"") -> PMQT | E35: =IFERROR(VLOOKUP($A35,'Lịch AP'!$A:$J,E$1,0),"") -> T1006 (Nha T) | F35: =IFERROR(VLOOKUP($A35,'Lịch AP'!$A:$J,F$1,0),"") -> SD21301 | G35: =IFERROR(VLOOKUP($A35,'Lịch AP'!$A:$J,G$1,0),"") -> baytt | H35: =IFERROR(VLOOKUP($A35,'Lịch AP'!$A:$J,H$1,0),"") -> COM108 | I35: =IFERROR(VLOOKUP($A35,'Lịch AP'!$A:$J,I$1,0),"") -> Nhập môn lập trình
A36: 19 | B36: =IFERROR(VLOOKUP($A36,'Lịch AP'!$A:$J,B$1,0),"") -> 46007 | C36: =IFERROR(VLOOKUP($A36,'Lịch AP'!$A:$J,C$1,0),"") -> 1 | D36: =IFERROR(VLOOKUP($A36,'Lịch AP'!$A:$J,D$1,0),"") -> PMQT | E36: =IFERROR(VLOOKUP($A36,'Lịch AP'!$A:$J,E$1,0),"") -> T1006 (Nha T) | F36: =IFERROR(VLOOKUP($A36,'Lịch AP'!$A:$J,F$1,0),"") -> SD21301 | G36: =IFERROR(VLOOKUP($A36,'Lịch AP'!$A:$J,G$1,0),"") -> baytt | H36: =IFERROR(VLOOKUP($A36,'Lịch AP'!$A:$J,H$1,0),"") -> COM108 | I36: =IFERROR(VLOOKUP($A36,'Lịch AP'!$A:$J,I$1,0),"") -> Nhập môn lập trình
A37: 20 | B37: =IFERROR(VLOOKUP($A37,'Lịch AP'!$A:$J,B$1,0),"") -> 46009 | C37: =IFERROR(VLOOKUP($A37,'Lịch AP'!$A:$J,C$1,0),"") -> 1 | D37: =IFERROR(VLOOKUP($A37,'Lịch AP'!$A:$J,D$1,0),"") -> PMQT | E37: =IFERROR(VLOOKUP($A37,'Lịch AP'!$A:$J,E$1,0),"") -> T1006 (Nha T) | F37: =IFERROR(VLOOKUP($A37,'Lịch AP'!$A:$J,F$1,0),"") -> SD21301 | G37: =IFERROR(VLOOKUP($A37,'Lịch AP'!$A:$J,G$1,0),"") -> baytt | H37: =IFERROR(VLOOKUP($A37,'Lịch AP'!$A:$J,H$1,0),"") -> COM108 | I37: =IFERROR(VLOOKUP($A37,'Lịch AP'!$A:$J,I$1,0),"") -> Nhập môn lập trình
A40: MỘT SỐ QUY ĐỊNH CẦN HẾT SỨC CHÚ Ý:
A41: 1. Đi học không đủ số buổi (Vắng hơn 3 buổi) | I41: ---> Failed môn
A42: 2. Điểm (quiz1+ quiz2+quiz3+quiz4+quiz5+quiz6+quiz7+quiz8)/8 <5 | I42: ---> Failed môn
...

Sheet Lịch AP
A1: # | B1: Ngày | C1: Ca học | D1: Khu | E1: Phòng | F1: Lớp | G1: Giảng viên | H1: Mã môn | I1: Tên môn | J1: Mô tả
A2: 1 | B2: 45965 | C2: 1 | D2: PMQT | E2: T1006 (Nha T) | F2: SD21301 | G2: baytt | H2: COM108 | I2: Nhập môn lập trình | J2: Tích hợp(LT+TH)
A3: 2 | B3: 45967 | C3: 1 | D3: PMQT | E3: T1006 (Nha T) | F3: SD21301 | G3: baytt | H3: COM108 | I3: Nhập môn lập trình | J3: Tích hợp(LT+TH)
A4: 3 | B4: 45969 | C4: 1 | D4: PMQT | E4: T1006 (Nha T) | F4: SD21301 | G4: baytt | H4: COM108 | I4: Nhập môn lập trình | J4: Tích hợp(LT+TH)
A5: 4 | B5: 45972 | C5: 1 | D5: PMQT | E5: T1006 (Nha T) | F5: SD21301 | G5: baytt | H5: COM108 | I5: Nhập môn lập trình | J5: Tích hợp(LT+TH)
A6: 5 | B6: 45974 | C6: 1 | D6: PMQT | E6: T1006 (Nha T) | F6: SD21301 | G6: baytt | H6: COM108 | I6: Nhập môn lập trình | J6: Tích hợp(LT+TH)
A7: 6 | B7: 45976 | C7: 1 | D7: PMQT | E7: T1006 (Nha T) | F7: SD21301 | G7: baytt | H7: COM108 | I7: Nhập môn lập trình | J7: Tích hợp(LT+TH)
A8: 7 | B8: 45979 | C8: 1 | D8: PMQT | E8: T1006 (Nha T) | F8: SD21301 | G8: baytt | H8: COM108 | I8: Nhập môn lập trình | J8: Tích hợp(LT+TH)
A9: 8 | B9: 45981 | C9: 1 | D9: PMQT | E9: T1006 (Nha T) | F9: SD21301 | G9: baytt | H9: COM108 | I9: Nhập môn lập trình | J9: Tích hợp(LT+TH)
A10: 9 | B10: 45983 | C10: 1 | D10: PMQT | E10: T1006 (Nha T) | F10: SD21301 | G10: baytt | H10: COM108 | I10: Nhập môn lập trình | J10: Tích hợp(LT+TH)
A11: 10 | B11: 45986 | C11: 1 | D11: PMQT | E11: T1006 (Nha T) | F11: SD21301 | G11: baytt | H11: COM108 | I11: Nhập môn lập trình | J11: Tích hợp(LT+TH)
A12: 11 | B12: 45988 | C12: 1 | D12: PMQT | E12: T1006 (Nha T) | F12: SD21301 | G12: baytt | H12: COM108 | I12: Nhập môn lập trình | J12: Tích hợp(LT+TH)
A13: 12 | B13: 45990 | C13: 1 | D13: PMQT | E13: T1006 (Nha T) | F13: SD21301 | G13: baytt | H13: COM108 | I13: Nhập môn lập trình | J13: Tích hợp(LT+TH)
... A22: 21 | B22: 46011 | C22: 1 | D22: PMQT | E22: T1006 (Nha T) | F22: SD21301 | G22: baytt | H22: COM108 | I22: Nhập môn lập trình | J22: Bảo vệ/Dự án
